Workbook

Sheet README
A1: Supplementary Experimental Data Workbook
A3: Manuscript | B3: A User-Space Virtualization Lab for Postgraduate Networking Education and Research in WMN, MANET, and WSN
A4: Purpose | B4: Structured supplementary-data workbook corresponding to the 30-run experimental protocol and aggregate results reported in the revised manuscript.
A5: Important provenance note | B5: The Raw_Run_Data sheet is an ILLUSTRATIVE/RECONSTRUCTED dataset generated from the published mean and sample-SD values in the manuscript. It is NOT the original laboratory raw data and must NOT be represented as measured raw data.
A6: Recommended use | B6: Use the workbook structure as a template for the actual per-run CSV/log export. Replace the illustrative values with the original measurements before public deposition or submission.
A7: Experimental repetitions | B7: 30 independent runs per traffic condition
A8: Measurement duration | B8: 300 s per run; first 30 s excluded as warm-up
A9: Packet payload | B9: 512 bytes UDP
A10: Statistics | B10: Mean ± sample standard deviation (n = 30)
A11: Primary metrics | B11: End-to-end delay, jitter, PDR, application throughput, CPU load

Sheet Experimental_Protocol
A1: Parameter | B1: Value | C1: Source/Role
A2: Physical topology | B2: Fixed five-node Raspberry Pi ad hoc network | C2: Experimental protocol
A3: Routing protocol | B3: User-space OLSR | C3: Experimental protocol
A4: Independent repetitions | B4: 30 runs per traffic condition | C4: Statistical basis
A5: Duration per run | B5: 300 s (5 min) | C5: Measurement protocol
A6: Warm-up excluded | B6: First 30 s | C6: Avoid startup transients
A7: UDP payload | B7: 512 bytes | C7: Experimental configuration
A8: Delay | B8: End-to-end application latency | C8: Performance metric
A9: Jitter | B9: RFC 3550 definition | C9: Performance metric
A10: PDR | B10: Successfully received / transmitted packets | C10: Performance metric
A11: Throughput | B11: Average application throughput | C11: Performance metric
A12: CPU load | B12: Average CPU utilization during each run | C12: Resource metric
A13: Statistical reporting | B13: Mean ± sample standard deviation (n=30) | C13: Table 8

Sheet Scenario_Config
A1: Scenario | B1: Node | C1: Role | D1: Message Type | E1: Source → Destination | F1: Interval / Trigger
A2: Substation Automation | B2: Node 1 | C2: SCADA Master | D2: Control Commands | E2: 1 → 2 | F2: On demand
A3: Substation Automation | B3: Node 2 | C3: Bay Controller | D3: Trip / Protection | E3: 2 → 3,4 | F3: Every 20 ms
A4: Substation Automation | B4: Node 3 | C4: IED #1 | D4: Measurement Reports | E4: 3 → 1 | F4: Every 50 ms
A5: Substation Automation | B5: Node 4 | C5: IED #2 | D5: Status / Alarm | E5: 4 → 1 | F5: Event-driven
A6: Substation Automation | B6: Node 5 | C6: RTU Sensor | D6: Temp. / Humidity | E6: 5 → 1 | F6: Every 1 s
A7: Smart Factory | B7: Node 1 | C7: Edge Controller | D7: Control Commands | E7: 1 → 2,3 | F7: Every 50 ms
A8: Smart Factory | B8: Node 2 | C8: Machine Ctrl. #1 | D8: Status Feedback | E8: 2 → 1 | F8: Every 50 ms
A9: Smart Factory | B9: Node 3 | C9: Machine Ctrl. #2 | D9: Conveyor Events | E9: 3 → 1 | F9: Event-driven
A10: Smart Factory | B10: Node 4 | C10: Sensor Gateway | D10: Temp. / Vibration | E10: 4 → 1,5 | F10: Every 100 ms
A11: Smart Factory | B11: Node 5 | C11: Maintenance Station | D11: Diagnostic Logs | E11: 5 → 1 | F11: Every 10 s
A12: Medical IoT | B12: Node 1 | C12: Monitoring Station | D12: Feedback Commands | E12: 1 → 2–5 | F12: On demand
... A21: Smart Vehicles | B21: Node 5 | C21: Emergency Vehicle | D21: Priority Request | E21: 5 → 1 | F21: On demand

Sheet Raw_Run_Data
A1: Scenario | B1: Traffic Type | C1: Run | D1: Measurement Duration (s) | E1: Warm-up Excluded (s) | F1: Packet Size (bytes) | G1: Delay (ms) | H1: Jitter (ms) | I1: PDR (%) | J1: Throughput (kbps) | K1: CPU Load (%)
A2: Substation Automation | B2: Real-Time Control | C2: 1 | D2: 300 | E2: 30 | F2: 512 | G2: 16.034169 | H2: 2.9669055 | I2: 97.100358 | J2: 253.50537 | K2: 19.617443
A3: Substation Automation | B3: Real-Time Control | C3: 2 | D3: 300 | E3: 30 | F3: 512 | G3: 16.392192 | H3: 3.0691977 | I3: 97.253797 | J3: 255.80695 | K3: 19.949893
A4: Substation Automation | B4: Real-Time Control | C4: 3 | D4: 300 | E4: 30 | F4: 512 | G4: 16.645792 | H4: 3.1416547 | I4: 97.362482 | J4: 257.43723 | K4: 20.185378
A5: Substation Automation | B5: Real-Time Control | C5: 4 | D5: 300 | E5: 30 | F5: 512 | G5: 16.854638 | H5: 3.2013252 | I5: 97.451988 | J5: 258.77982 | K5: 20.379307
A6: Substation Automation | B6: Real-Time Control | C6: 5 | D6: 300 | E6: 30 | F6: 512 | G6: 17.03365 | H6: 3.2524714 | I6: 97.528707 | J6: 259.93061 | K6: 20.545532
A7: Substation Automation | B7: Real-Time Control | C7: 6 | D7: 300 | E7: 30 | F7: 512 | G7: 17.197744 | H7: 3.2993553 | I7: 97.599033 | J7: 260.98549 | K7: 20.697905
A8: Substation Automation | B8: Real-Time Control | C8: 7 | D8: 300 | E8: 30 | F8: 512 | G8: 17.34692 | H8: 3.3419771 | I8: 97.662966 | J8: 261.94448 | K8: 20.836426
A9: Substation Automation | B9: Real-Time Control | C9: 8 | D9: 300 | E9: 30 | F9: 512 | G9: 17.481178 | H9: 3.3803367 | I9: 97.720505 | J9: 262.80758 | K9: 20.961094
A10: Substation Automation | B10: Real-Time Control | C10: 9 | D10: 300 | E10: 30 | F10: 512 | G10: 17.615437 | H10: 3.4186963 | I10: 97.778044 | J10: 263.67067 | K10: 21.085763
A11: Substation Automation | B11: Real-Time Control | C11: 10 | D11: 300 | E11: 30 | F11: 512 | G11: 17.749696 | H11: 3.4570559 | I11: 97.835584 | J11: 264.53376 | K11: 21.210432
A12: Substation Automation | B12: Real-Time Control | C12: 11 | D12: 300 | E12: 30 | F12: 512 | G12: 17.883954 | H12: 3.4954155 | I12: 97.893123 | J12: 265.39685 | K12: 21.3351
A13: Substation Automation | B13: Real-Time Control | C13: 12 | D13: 300 | E13: 30 | F13: 512 | G13: 18.018213 | H13: 3.5337751 | I13: 97.950663 | J13: 266.25994 | K13: 21.459769
... A331: Smart Vehicles | B331: Topology Change | C331: 30 | D331: 300 | E331: 30 | F331: 512 | G331: 32.065473 | H331: 6.0996418 | I331: 97.749463 | J331: 300.1601 | K331: 25.582557

Sheet Reported_Aggregates
A1: Scenario | B1: Traffic Type | C1: Delay Mean (ms) | D1: Delay SD (ms) | E1: Jitter Mean (ms) | F1: Jitter SD (ms) | G1: PDR Mean (%) | H1: PDR SD (%) | I1: Throughput Mean (kbps) | J1: Throughput SD (kbps) | K1: CPU Mean (%) | L1: CPU SD (%)
A2: Substation Automation | B2: Real-Time Control | C2: 18.6 | D2: 1.4 | E2: 3.7 | F2: 0.4 | G2: 98.2 | H2: 0.6 | I2: 270 | J2: 9 | K2: 22 | L2: 1.3
A3: Substation Automation | B3: Supervisory Data | C3: 41.8 | D3: 2.3 | E3: 5.2 | F3: 0.6 | G3: 99.4 | H3: 0.3 | I3: 380 | J3: 12 | K3: 20 | L3: 1.1
A4: Smart Factory | B4: Control Traffic | C4: 22.4 | D4: 1.5 | E4: 4.8 | F4: 0.5 | G4: 98.6 | H4: 0.5 | I4: 240 | J4: 8 | K4: 24 | L4: 1.5
A5: Smart Factory | B5: Sensor Data | C5: 38.9 | D5: 2.1 | E5: 6.3 | F5: 0.8 | G5: 99.1 | H5: 0.4 | I5: 420 | J5: 15 | K5: 23 | L5: 1.2
A6: Smart Factory | B6: Maintenance Upload | C6: 76.2 | D6: 4.8 | E6: 12.1 | F6: 1 | G6: 99.5 | H6: 0.2 | I6: 800 | J6: 18 | K6: 25 | L6: 1.4
A7: Medical IoT | B7: ECG Stream | C7: 19.7 | D7: 1.2 | E7: 3.2 | F7: 0.3 | G7: 97.8 | H7: 0.8 | I7: 260 | J7: 10 | K7: 28 | L7: 1.6
A8: Medical IoT | B8: Vital Signs | C8: 33.2 | D8: 1.9 | E8: 5.5 | F8: 0.7 | G8: 99 | H8: 0.4 | I8: 330 | J8: 11 | K8: 19.4 | L8: 1.1
A9: Medical IoT | B9: Link Disruption | C9: 41.5 | D9: 2.8 | E9: 6.1 | F9: 0.9 | G9: 95.4 | H9: 1.2 | I9: 310 | J9: 13 | K9: 22.1 | L9: 1.4
A10: Smart Vehicles | B10: CAM | C10: 17.5 | D10: 1.1 | E10: 2.9 | F10: 0.3 | G10: 98.5 | H10: 0.5 | I10: 310 | J10: 12 | K10: 22 | L10: 1.3
A11: Smart Vehicles | B11: DENM | C11: 21 | D11: 1.4 | E11: 3.6 | F11: 0.4 | G11: 97.9 | H11: 0.6 | I11: 250 | J11: 10 | K11: 21.2 | L11: 1.2
A12: Smart Vehicles | B12: Topology Change | C12: 28.4 | D12: 2 | E12: 5 | F12: 0.6 | G12: 96.1 | H12: 0.9 | I12: 280 | J12: 11 | K12: 23.2 | L12: 1.3

Sheet Calculated_Summary
A1: Scenario | B1: Traffic Type | C1: Delay Mean | D1: Delay SD | E1: Jitter Mean | F1: Jitter SD | G1: PDR Mean | H1: PDR SD | I1: Throughput Mean | J1: Throughput SD | K1: CPU Mean | L1: CPU SD
A2: Substation Automation | B2: Real-Time Control | C2: =AVERAGEIFS(Raw_Run_Data!$G:$G,Raw_Run_Data!$A:$A,$A2,Raw_Run_Data!$B:$B,$B2) -> 18.6 | D2: =IFERROR(__xludf.DUMMYFUNCTION("STDEV.S(FILTER(Raw_Run_Data!$G:$G,(Raw_Run_Data!$A:$A=$A2)*(Raw_Run_Data!$B:$B=$B2)))"),1.4000000000000021) -> 1.4 | E2: =AVERAGEIFS(Raw_Run_Data!$H:$H,Raw_Run_Data!$A:$A,$A2,Raw_Run_Data!$B:$B,$B2) -> 3.7 | F2: =IFERROR(__xludf.DUMMYFUNCTION("STDEV.S(FILTER(Raw_Run_Data!$H:$H,(Raw_Run_Data!$A:$A=$A2)*(Raw_Run_Data!$B:$B=$B2)))"),0.4000000000000001) -> 0.4 | G2: =AVERAGEIFS(Raw_Run_Data!$I:$I,Raw_Run_Data!$A:$A,$A2,Raw_Run_Data!$B:$B,$B2) -> 98.2 | H2: =IFERROR(__xludf.DUMMYFUNCTION("STDEV.S(FILTER(Raw_Run_Data!$I:$I,(Raw_Run_Data!$A:$A=$A2)*(Raw_Run_Data!$B:$B=$B2)))"),0.5999999999999956) -> 0.6 | I2: =AVERAGEIFS(Raw_Run_Data!$J:$J,Raw_Run_Data!$A:$A,$A2,Raw_Run_Data!$B:$B,$B2) -> 270 | J2: =IFERROR(__xludf.DUMMYFUNCTION("STDEV.S(FILTER(Raw_Run_Data!$J:$J,(Raw_Run_Data!$A:$A=$A2)*(Raw_Run_Data!$B:$B=$B2)))"),8.999999999999988) -> 9 | K2: =AVERAGEIFS(Raw_Run_Data!$K:$K,Raw_Run_Data!$A:$A,$A2,Raw_Run_Data!$B:$B,$B2) -> 22 | L2: =IFERROR(__xludf.DUMMYFUNCTION("STDEV.S(FILTER(Raw_Run_Data!$K:$K,(Raw_Run_Data!$A:$A=$A2)*(Raw_Run_Data!$B:$B=$B2)))"),1.3000000000000003) -> 1.3
A3: Substation Automation | B3: Supervisory Data | C3: =AVERAGEIFS(Raw_Run_Data!$G:$G,Raw_Run_Data!$A:$A,$A3,Raw_Run_Data!$B:$B,$B3) -> 41.8 | D3: =IFERROR(__xludf.DUMMYFUNCTION("STDEV.S(FILTER(Raw_Run_Data!$G:$G,(Raw_Run_Data!$A:$A=$A3)*(Raw_Run_Data!$B:$B=$B3)))"),2.3000000000000034) -> 2.3 | E3: =AVERAGEIFS(Raw_Run_Data!$H:$H,Raw_Run_Data!$A:$A,$A3,Raw_Run_Data!$B:$B,$B3) -> 5.2 | F3: =IFERROR(__xludf.DUMMYFUNCTION("STDEV.S(FILTER(Raw_Run_Data!$H:$H,(Raw_Run_Data!$A:$A=$A3)*(Raw_Run_Data!$B:$B=$B3)))"),0.6000000000000009) -> 0.6 | G3: =AVERAGEIFS(Raw_Run_Data!$I:$I,Raw_Run_Data!$A:$A,$A3,Raw_Run_Data!$B:$B,$B3) -> 99.4 | H3: =IFERROR(__xludf.DUMMYFUNCTION("STDEV.S(FILTER(Raw_Run_Data!$I:$I,(Raw_Run_Data!$A:$A=$A3)*(Raw_Run_Data!$B:$B=$B3)))"),0.29999999999998955) -> 0.3 | I3: =AVERAGEIFS(Raw_Run_Data!$J:$J,Raw_Run_Data!$A:$A,$A3,Raw_Run_Data!$B:$B,$B3) -> 380 | J3: =IFERROR(__xludf.DUMMYFUNCTION("STDEV.S(FILTER(Raw_Run_Data!$J:$J,(Raw_Run_Data!$A:$A=$A3)*(Raw_Run_Data!$B:$B=$B3)))"),11.999999999999998) -> 12 | K3: =AVERAGEIFS(Raw_Run_Data!$K:$K,Raw_Run_Data!$A:$A,$A3,Raw_Run_Data!$B:$B,$B3) -> 20 | L3: =IFERROR(__xludf.DUMMYFUNCTION("STDEV.S(FILTER(Raw_Run_Data!$K:$K,(Raw_Run_Data!$A:$A=$A3)*(Raw_Run_Data!$B:$B=$B3)))"),1.0999999999999999) -> 1.1
A4: Smart Factory | B4: Control Traffic | C4: =AVERAGEIFS(Raw_Run_Data!$G:$G,Raw_Run_Data!$A:$A,$A4,Raw_Run_Data!$B:$B,$B4) -> 22.4 | D4: =IFERROR(__xludf.DUMMYFUNCTION("STDEV.S(FILTER(Raw_Run_Data!$G:$G,(Raw_Run_Data!$A:$A=$A4)*(Raw_Run_Data!$B:$B=$B4)))"),1.5000000000000013) -> 1.5 | E4: =AVERAGEIFS(Raw_Run_Data!$H:$H,Raw_Run_Data!$A:$A,$A4,Raw_Run_Data!$B:$B,$B4) -> 4.8 | F4: =IFERROR(__xludf.DUMMYFUNCTION("STDEV.S(FILTER(Raw_Run_Data!$H:$H,(Raw_Run_Data!$A:$A=$A4)*(Raw_Run_Data!$B:$B=$B4)))"),0.5000000000000002) -> 0.5 | G4: =AVERAGEIFS(Raw_Run_Data!$I:$I,Raw_Run_Data!$A:$A,$A4,Raw_Run_Data!$B:$B,$B4) -> 98.6 | H4: =IFERROR(__xludf.DUMMYFUNCTION("STDEV.S(FILTER(Raw_Run_Data!$I:$I,(Raw_Run_Data!$A:$A=$A4)*(Raw_Run_Data!$B:$B=$B4)))"),0.49999999999999883) -> 0.5 | I4: =AVERAGEIFS(Raw_Run_Data!$J:$J,Raw_Run_Data!$A:$A,$A4,Raw_Run_Data!$B:$B,$B4) -> 240 | J4: =IFERROR(__xludf.DUMMYFUNCTION("STDEV.S(FILTER(Raw_Run_Data!$J:$J,(Raw_Run_Data!$A:$A=$A4)*(Raw_Run_Data!$B:$B=$B4)))"),7.999999999999976) -> 8 | K4: =AVERAGEIFS(Raw_Run_Data!$K:$K,Raw_Run_Data!$A:$A,$A4,Raw_Run_Data!$B:$B,$B4) -> 24 | L4: =IFERROR(__xludf.DUMMYFUNCTION("STDEV.S(FILTER(Raw_Run_Data!$K:$K,(Raw_Run_Data!$A:$A=$A4)*(Raw_Run_Data!$B:$B=$B4)))"),1.499999999999999) -> 1.5
A5: Smart Factory | B5: Sensor Data | C5: =AVERAGEIFS(Raw_Run_Data!$G:$G,Raw_Run_Data!$A:$A,$A5,Raw_Run_Data!$B:$B,$B5) -> 38.9 | D5: =IFERROR(__xludf.DUMMYFUNCTION("STDEV.S(FILTER(Raw_Run_Data!$G:$G,(Raw_Run_Data!$A:$A=$A5)*(Raw_Run_Data!$B:$B=$B5)))"),2.099999999999994) -> 2.1 | E5: =AVERAGEIFS(Raw_Run_Data!$H:$H,Raw_Run_Data!$A:$A,$A5,Raw_Run_Data!$B:$B,$B5) -> 6.3 | F5: =IFERROR(__xludf.DUMMYFUNCTION("STDEV.S(FILTER(Raw_Run_Data!$H:$H,(Raw_Run_Data!$A:$A=$A5)*(Raw_Run_Data!$B:$B=$B5)))"),0.8000000000000003) -> 0.8 | G5: =AVERAGEIFS(Raw_Run_Data!$I:$I,Raw_Run_Data!$A:$A,$A5,Raw_Run_Data!$B:$B,$B5) -> 99.1 | H5: =IFERROR(__xludf.DUMMYFUNCTION("STDEV.S(FILTER(Raw_Run_Data!$I:$I,(Raw_Run_Data!$A:$A=$A5)*(Raw_Run_Data!$B:$B=$B5)))"),0.3999999999999896) -> 0.4 | I5: =AVERAGEIFS(Raw_Run_Data!$J:$J,Raw_Run_Data!$A:$A,$A5,Raw_Run_Data!$B:$B,$B5) -> 420 | J5: =IFERROR(__xludf.DUMMYFUNCTION("STDEV.S(FILTER(Raw_Run_Data!$J:$J,(Raw_Run_Data!$A:$A=$A5)*(Raw_Run_Data!$B:$B=$B5)))"),14.999999999999938) -> 15 | K5: =AVERAGEIFS(Raw_Run_Data!$K:$K,Raw_Run_Data!$A:$A,$A5,Raw_Run_Data!$B:$B,$B5) -> 23 | L5: =IFERROR(__xludf.DUMMYFUNCTION("STDEV.S(FILTER(Raw_Run_Data!$K:$K,(Raw_Run_Data!$A:$A=$A5)*(Raw_Run_Data!$B:$B=$B5)))"),1.1999999999999997) -> 1.2
A6: Smart Factory | B6: Maintenance Upload | C6: =AVERAGEIFS(Raw_Run_Data!$G:$G,Raw_Run_Data!$A:$A,$A6,Raw_Run_Data!$B:$B,$B6) -> 76.2 | D6: =IFERROR(__xludf.DUMMYFUNCTION("STDEV.S(FILTER(Raw_Run_Data!$G:$G,(Raw_Run_Data!$A:$A=$A6)*(Raw_Run_Data!$B:$B=$B6)))"),4.800000000000002) -> 4.8 | E6: =AVERAGEIFS(Raw_Run_Data!$H:$H,Raw_Run_Data!$A:$A,$A6,Raw_Run_Data!$B:$B,$B6) -> 12.1 | F6: =IFERROR(__xludf.DUMMYFUNCTION("STDEV.S(FILTER(Raw_Run_Data!$H:$H,(Raw_Run_Data!$A:$A=$A6)*(Raw_Run_Data!$B:$B=$B6)))"),0.999999999999998) -> 1 | G6: =AVERAGEIFS(Raw_Run_Data!$I:$I,Raw_Run_Data!$A:$A,$A6,Raw_Run_Data!$B:$B,$B6) -> 99.5 | H6: =IFERROR(__xludf.DUMMYFUNCTION("STDEV.S(FILTER(Raw_Run_Data!$I:$I,(Raw_Run_Data!$A:$A=$A6)*(Raw_Run_Data!$B:$B=$B6)))"),0.19999999999998622) -> 0.2 | I6: =AVERAGEIFS(Raw_Run_Data!$J:$J,Raw_Run_Data!$A:$A,$A6,Raw_Run_Data!$B:$B,$B6) -> 800 | J6: =IFERROR(__xludf.DUMMYFUNCTION("STDEV.S(FILTER(Raw_Run_Data!$J:$J,(Raw_Run_Data!$A:$A=$A6)*(Raw_Run_Data!$B:$B=$B6)))"),18.00000000000007) -> 18 | K6: =AVERAGEIFS(Raw_Run_Data!$K:$K,Raw_Run_Data!$A:$A,$A6,Raw_Run_Data!$B:$B,$B6) -> 25 | L6: =IFERROR(__xludf.DUMMYFUNCTION("STDEV.S(FILTER(Raw_Run_Data!$K:$K,(Raw_Run_Data!$A:$A=$A6)*(Raw_Run_Data!$B:$B=$B6)))"),1.400000000000003) -> 1.4
A7: Medical IoT | B7: ECG Stream | C7: =AVERAGEIFS(Raw_Run_Data!$G:$G,Raw_Run_Data!$A:$A,$A7,Raw_Run_Data!$B:$B,$B7) -> 19.7 | D7: =IFERROR(__xludf.DUMMYFUNCTION("STDEV.S(FILTER(Raw_Run_Data!$G:$G,(Raw_Run_Data!$A:$A=$A7)*(Raw_Run_Data!$B:$B=$B7)))"),1.2000000000000002) -> 1.2 | E7: =AVERAGEIFS(Raw_Run_Data!$H:$H,Raw_Run_Data!$A:$A,$A7,Raw_Run_Data!$B:$B,$B7) -> 3.2 | F7: =IFERROR(__xludf.DUMMYFUNCTION("STDEV.S(FILTER(Raw_Run_Data!$H:$H,(Raw_Run_Data!$A:$A=$A7)*(Raw_Run_Data!$B:$B=$B7)))"),0.3000000000000005) -> 0.3 | G7: =AVERAGEIFS(Raw_Run_Data!$I:$I,Raw_Run_Data!$A:$A,$A7,Raw_Run_Data!$B:$B,$B7) -> 97.8 | H7: =IFERROR(__xludf.DUMMYFUNCTION("STDEV.S(FILTER(Raw_Run_Data!$I:$I,(Raw_Run_Data!$A:$A=$A7)*(Raw_Run_Data!$B:$B=$B7)))"),0.8000000000000062) -> 0.8 | I7: =AVERAGEIFS(Raw_Run_Data!$J:$J,Raw_Run_Data!$A:$A,$A7,Raw_Run_Data!$B:$B,$B7) -> 260 | J7: =IFERROR(__xludf.DUMMYFUNCTION("STDEV.S(FILTER(Raw_Run_Data!$J:$J,(Raw_Run_Data!$A:$A=$A7)*(Raw_Run_Data!$B:$B=$B7)))"),9.999999999999984) -> 10 | K7: =AVERAGEIFS(Raw_Run_Data!$K:$K,Raw_Run_Data!$A:$A,$A7,Raw_Run_Data!$B:$B,$B7) -> 28 | L7: =IFERROR(__xludf.DUMMYFUNCTION("STDEV.S(FILTER(Raw_Run_Data!$K:$K,(Raw_Run_Data!$A:$A=$A7)*(Raw_Run_Data!$B:$B=$B7)))"),1.6000000000000012) -> 1.6
A8: Medical IoT | B8: Vital Signs | C8: =AVERAGEIFS(Raw_Run_Data!$G:$G,Raw_Run_Data!$A:$A,$A8,Raw_Run_Data!$B:$B,$B8) -> 33.2 | D8: =IFERROR(__xludf.DUMMYFUNCTION("STDEV.S(FILTER(Raw_Run_Data!$G:$G,(Raw_Run_Data!$A:$A=$A8)*(Raw_Run_Data!$B:$B=$B8)))"),1.899999999999999) -> 1.9 | E8: =AVERAGEIFS(Raw_Run_Data!$H:$H,Raw_Run_Data!$A:$A,$A8,Raw_Run_Data!$B:$B,$B8) -> 5.5 | F8: =IFERROR(__xludf.DUMMYFUNCTION("STDEV.S(FILTER(Raw_Run_Data!$H:$H,(Raw_Run_Data!$A:$A=$A8)*(Raw_Run_Data!$B:$B=$B8)))"),0.6999999999999995) -> 0.7 | G8: =AVERAGEIFS(Raw_Run_Data!$I:$I,Raw_Run_Data!$A:$A,$A8,Raw_Run_Data!$B:$B,$B8) -> 99 | H8: =IFERROR(__xludf.DUMMYFUNCTION("STDEV.S(FILTER(Raw_Run_Data!$I:$I,(Raw_Run_Data!$A:$A=$A8)*(Raw_Run_Data!$B:$B=$B8)))"),0.3999999999999896) -> 0.4 | I8: =AVERAGEIFS(Raw_Run_Data!$J:$J,Raw_Run_Data!$A:$A,$A8,Raw_Run_Data!$B:$B,$B8) -> 330 | J8: =IFERROR(__xludf.DUMMYFUNCTION("STDEV.S(FILTER(Raw_Run_Data!$J:$J,(Raw_Run_Data!$A:$A=$A8)*(Raw_Run_Data!$B:$B=$B8)))"),10.999999999999977) -> 11 | K8: =AVERAGEIFS(Raw_Run_Data!$K:$K,Raw_Run_Data!$A:$A,$A8,Raw_Run_Data!$B:$B,$B8) -> 19.4 | L8: =IFERROR(__xludf.DUMMYFUNCTION("STDEV.S(FILTER(Raw_Run_Data!$K:$K,(Raw_Run_Data!$A:$A=$A8)*(Raw_Run_Data!$B:$B=$B8)))"),1.1000000000000005) -> 1.1
A9: Medical IoT | B9: Link Disruption | C9: =AVERAGEIFS(Raw_Run_Data!$G:$G,Raw_Run_Data!$A:$A,$A9,Raw_Run_Data!$B:$B,$B9) -> 41.5 | D9: =IFERROR(__xludf.DUMMYFUNCTION("STDEV.S(FILTER(Raw_Run_Data!$G:$G,(Raw_Run_Data!$A:$A=$A9)*(Raw_Run_Data!$B:$B=$B9)))"),2.800000000000002) -> 2.8 | E9: =AVERAGEIFS(Raw_Run_Data!$H:$H,Raw_Run_Data!$A:$A,$A9,Raw_Run_Data!$B:$B,$B9) -> 6.1 | F9: =IFERROR(__xludf.DUMMYFUNCTION("STDEV.S(FILTER(Raw_Run_Data!$H:$H,(Raw_Run_Data!$A:$A=$A9)*(Raw_Run_Data!$B:$B=$B9)))"),0.8999999999999995) -> 0.9 | G9: =AVERAGEIFS(Raw_Run_Data!$I:$I,Raw_Run_Data!$A:$A,$A9,Raw_Run_Data!$B:$B,$B9) -> 95.4 | H9: =IFERROR(__xludf.DUMMYFUNCTION("STDEV.S(FILTER(Raw_Run_Data!$I:$I,(Raw_Run_Data!$A:$A=$A9)*(Raw_Run_Data!$B:$B=$B9)))"),1.2000000000000004) -> 1.2 | I9: =AVERAGEIFS(Raw_Run_Data!$J:$J,Raw_Run_Data!$A:$A,$A9,Raw_Run_Data!$B:$B,$B9) -> 310 | J9: =IFERROR(__xludf.DUMMYFUNCTION("STDEV.S(FILTER(Raw_Run_Data!$J:$J,(Raw_Run_Data!$A:$A=$A9)*(Raw_Run_Data!$B:$B=$B9)))"),12.999999999999954) -> 13 | K9: =AVERAGEIFS(Raw_Run_Data!$K:$K,Raw_Run_Data!$A:$A,$A9,Raw_Run_Data!$B:$B,$B9) -> 22.1 | L9: =IFERROR(__xludf.DUMMYFUNCTION("STDEV.S(FILTER(Raw_Run_Data!$K:$K,(Raw_Run_Data!$A:$A=$A9)*(Raw_Run_Data!$B:$B=$B9)))"),1.4000000000000021) -> 1.4
A10: Smart Vehicles | B10: CAM | C10: =AVERAGEIFS(Raw_Run_Data!$G:$G,Raw_Run_Data!$A:$A,$A10,Raw_Run_Data!$B:$B,$B10) -> 17.5 | D10: =IFERROR(__xludf.DUMMYFUNCTION("STDEV.S(FILTER(Raw_Run_Data!$G:$G,(Raw_Run_Data!$A:$A=$A10)*(Raw_Run_Data!$B:$B=$B10)))"),1.1) -> 1.1 | E10: =AVERAGEIFS(Raw_Run_Data!$H:$H,Raw_Run_Data!$A:$A,$A10,Raw_Run_Data!$B:$B,$B10) -> 2.9 | F10: =IFERROR(__xludf.DUMMYFUNCTION("STDEV.S(FILTER(Raw_Run_Data!$H:$H,(Raw_Run_Data!$A:$A=$A10)*(Raw_Run_Data!$B:$B=$B10)))"),0.30000000000000004) -> 0.3 | G10: =AVERAGEIFS(Raw_Run_Data!$I:$I,Raw_Run_Data!$A:$A,$A10,Raw_Run_Data!$B:$B,$B10) -> 98.5 | H10: =IFERROR(__xludf.DUMMYFUNCTION("STDEV.S(FILTER(Raw_Run_Data!$I:$I,(Raw_Run_Data!$A:$A=$A10)*(Raw_Run_Data!$B:$B=$B10)))"),0.49999999999999883) -> 0.5 | I10: =AVERAGEIFS(Raw_Run_Data!$J:$J,Raw_Run_Data!$A:$A,$A10,Raw_Run_Data!$B:$B,$B10) -> 310 | J10: =IFERROR(__xludf.DUMMYFUNCTION("STDEV.S(FILTER(Raw_Run_Data!$J:$J,(Raw_Run_Data!$A:$A=$A10)*(Raw_Run_Data!$B:$B=$B10)))"),11.999999999999998) -> 12 | K10: =AVERAGEIFS(Raw_Run_Data!$K:$K,Raw_Run_Data!$A:$A,$A10,Raw_Run_Data!$B:$B,$B10) -> 22 | L10: =IFERROR(__xludf.DUMMYFUNCTION("STDEV.S(FILTER(Raw_Run_Data!$K:$K,(Raw_Run_Data!$A:$A=$A10)*(Raw_Run_Data!$B:$B=$B10)))"),1.3000000000000003) -> 1.3
A11: Smart Vehicles | B11: DENM | C11: =AVERAGEIFS(Raw_Run_Data!$G:$G,Raw_Run_Data!$A:$A,$A11,Raw_Run_Data!$B:$B,$B11) -> 21 | D11: =IFERROR(__xludf.DUMMYFUNCTION("STDEV.S(FILTER(Raw_Run_Data!$G:$G,(Raw_Run_Data!$A:$A=$A11)*(Raw_Run_Data!$B:$B=$B11)))"),1.400000000000003) -> 1.4 | E11: =AVERAGEIFS(Raw_Run_Data!$H:$H,Raw_Run_Data!$A:$A,$A11,Raw_Run_Data!$B:$B,$B11) -> 3.6 | F11: =IFERROR(__xludf.DUMMYFUNCTION("STDEV.S(FILTER(Raw_Run_Data!$H:$H,(Raw_Run_Data!$A:$A=$A11)*(Raw_Run_Data!$B:$B=$B11)))"),0.4) -> 0.4 | G11: =AVERAGEIFS(Raw_Run_Data!$I:$I,Raw_Run_Data!$A:$A,$A11,Raw_Run_Data!$B:$B,$B11) -> 97.9 | H11: =IFERROR(__xludf.DUMMYFUNCTION("STDEV.S(FILTER(Raw_Run_Data!$I:$I,(Raw_Run_Data!$A:$A=$A11)*(Raw_Run_Data!$B:$B=$B11)))"),0.5999999999999984) -> 0.6 | I11: =AVERAGEIFS(Raw_Run_Data!$J:$J,Raw_Run_Data!$A:$A,$A11,Raw_Run_Data!$B:$B,$B11) -> 250 | J11: =IFERROR(__xludf.DUMMYFUNCTION("STDEV.S(FILTER(Raw_Run_Data!$J:$J,(Raw_Run_Data!$A:$A=$A11)*(Raw_Run_Data!$B:$B=$B11)))"),9.999999999999968) -> 10 | K11: =AVERAGEIFS(Raw_Run_Data!$K:$K,Raw_Run_Data!$A:$A,$A11,Raw_Run_Data!$B:$B,$B11) -> 21.2 | L11: =IFERROR(__xludf.DUMMYFUNCTION("STDEV.S(FILTER(Raw_Run_Data!$K:$K,(Raw_Run_Data!$A:$A=$A11)*(Raw_Run_Data!$B:$B=$B11)))"),1.2000000000000002) -> 1.2
A12: Smart Vehicles | B12: Topology Change | C12: =AVERAGEIFS(Raw_Run_Data!$G:$G,Raw_Run_Data!$A:$A,$A12,Raw_Run_Data!$B:$B,$B12) -> 28.4 | D12: =IFERROR(__xludf.DUMMYFUNCTION("STDEV.S(FILTER(Raw_Run_Data!$G:$G,(Raw_Run_Data!$A:$A=$A12)*(Raw_Run_Data!$B:$B=$B12)))"),2.0000000000000004) -> 2 | E12: =AVERAGEIFS(Raw_Run_Data!$H:$H,Raw_Run_Data!$A:$A,$A12,Raw_Run_Data!$B:$B,$B12) -> 5 | F12: =IFERROR(__xludf.DUMMYFUNCTION("STDEV.S(FILTER(Raw_Run_Data!$H:$H,(Raw_Run_Data!$A:$A=$A12)*(Raw_Run_Data!$B:$B=$B12)))"),0.6000000000000001) -> 0.6 | G12: =AVERAGEIFS(Raw_Run_Data!$I:$I,Raw_Run_Data!$A:$A,$A12,Raw_Run_Data!$B:$B,$B12) -> 96.1 | H12: =IFERROR(__xludf.DUMMYFUNCTION("STDEV.S(FILTER(Raw_Run_Data!$I:$I,(Raw_Run_Data!$A:$A=$A12)*(Raw_Run_Data!$B:$B=$B12)))"),0.8999999999999947) -> 0.9 | I12: =AVERAGEIFS(Raw_Run_Data!$J:$J,Raw_Run_Data!$A:$A,$A12,Raw_Run_Data!$B:$B,$B12) -> 280 | J12: =IFERROR(__xludf.DUMMYFUNCTION("STDEV.S(FILTER(Raw_Run_Data!$J:$J,(Raw_Run_Data!$A:$A=$A12)*(Raw_Run_Data!$B:$B=$B12)))"),10.999999999999977) -> 11 | K12: =AVERAGEIFS(Raw_Run_Data!$K:$K,Raw_Run_Data!$A:$A,$A12,Raw_Run_Data!$B:$B,$B12) -> 23.2 | L12: =IFERROR(__xludf.DUMMYFUNCTION("STDEV.S(FILTER(Raw_Run_Data!$K:$K,(Raw_Run_Data!$A:$A=$A12)*(Raw_Run_Data!$B:$B=$B12)))"),1.3000000000000003) -> 1.3

Sheet QC_Check
A1: Scenario | B1: Traffic Type | C1: Metric | D1: Target Mean | E1: Target SD | F1: Calculated Mean | G1: Calculated SD | H1: Status
A2: Substation Automation | B2: Real-Time Control | C2: Delay (ms) | D2: =Reported_Aggregates!B2 -> Real-Time Control | E2: =Reported_Aggregates!C2 -> 18.6 | F2: =Calculated_Summary!C2 -> 18.6 | G2: =Calculated_Summary!D2 -> 1.4
A3: Substation Automation | B3: Real-Time Control | C3: Jitter (ms) | D3: =Reported_Aggregates!D2 -> 1.4 | E3: =Reported_Aggregates!E2 -> 3.7 | F3: =Calculated_Summary!E2 -> 3.7 | G3: =Calculated_Summary!F2 -> 0.4
A4: Substation Automation | B4: Real-Time Control | C4: PDR (%) | D4: =Reported_Aggregates!F2 -> 0.4 | E4: =Reported_Aggregates!G2 -> 98.2 | F4: =Calculated_Summary!G2 -> 98.2 | G4: =Calculated_Summary!H2 -> 0.6
A5: Substation Automation | B5: Real-Time Control | C5: Throughput (kbps) | D5: =Reported_Aggregates!H2 -> 0.6 | E5: =Reported_Aggregates!I2 -> 270 | F5: =Calculated_Summary!I2 -> 270 | G5: =Calculated_Summary!J2 -> 9
A6: Substation Automation | B6: Real-Time Control | C6: CPU Load (%) | D6: =Reported_Aggregates!J2 -> 9 | E6: =Reported_Aggregates!K2 -> 22 | F6: =Calculated_Summary!K2 -> 22 | G6: =Calculated_Summary!L2 -> 1.3
A7: Substation Automation | B7: Supervisory Data | C7: Delay (ms) | D7: =Reported_Aggregates!B3 -> Supervisory Data | E7: =Reported_Aggregates!C3 -> 41.8 | F7: =Calculated_Summary!C3 -> 41.8 | G7: =Calculated_Summary!D3 -> 2.3
A8: Substation Automation | B8: Supervisory Data | C8: Jitter (ms) | D8: =Reported_Aggregates!D3 -> 2.3 | E8: =Reported_Aggregates!E3 -> 5.2 | F8: =Calculated_Summary!E3 -> 5.2 | G8: =Calculated_Summary!F3 -> 0.6
A9: Substation Automation | B9: Supervisory Data | C9: PDR (%) | D9: =Reported_Aggregates!F3 -> 0.6 | E9: =Reported_Aggregates!G3 -> 99.4 | F9: =Calculated_Summary!G3 -> 99.4 | G9: =Calculated_Summary!H3 -> 0.3
A10: Substation Automation | B10: Supervisory Data | C10: Throughput (kbps) | D10: =Reported_Aggregates!H3 -> 0.3 | E10: =Reported_Aggregates!I3 -> 380 | F10: =Calculated_Summary!I3 -> 380 | G10: =Calculated_Summary!J3 -> 12
A11: Substation Automation | B11: Supervisory Data | C11: CPU Load (%) | D11: =Reported_Aggregates!J3 -> 12 | E11: =Reported_Aggregates!K3 -> 20 | F11: =Calculated_Summary!K3 -> 20 | G11: =Calculated_Summary!L3 -> 1.1
A12: Smart Factory | B12: Control Traffic | C12: Delay (ms) | D12: =Reported_Aggregates!B4 -> Control Traffic | E12: =Reported_Aggregates!C4 -> 22.4 | F12: =Calculated_Summary!C4 -> 22.4 | G12: =Calculated_Summary!D4 -> 1.5
A13: Smart Factory | B13: Control Traffic | C13: Jitter (ms) | D13: =Reported_Aggregates!D4 -> 1.5 | E13: =Reported_Aggregates!E4 -> 4.8 | F13: =Calculated_Summary!E4 -> 4.8 | G13: =Calculated_Summary!F4 -> 0.5
A14: Smart Factory | B14: Control Traffic | C14: PDR (%) | D14: =Reported_Aggregates!F4 -> 0.5 | E14: =Reported_Aggregates!G4 -> 98.6 | F14: =Calculated_Summary!G4 -> 98.6 | G14: =Calculated_Summary!H4 -> 0.5
A15: Smart Factory | B15: Control Traffic | C15: Throughput (kbps) | D15: =Reported_Aggregates!H4 -> 0.5 | E15: =Reported_Aggregates!I4 -> 240 | F15: =Calculated_Summary!I4 -> 240 | G15: =Calculated_Summary!J4 -> 8
A16: Smart Factory | B16: Control Traffic | C16: CPU Load (%) | D16: =Reported_Aggregates!J4 -> 8 | E16: =Reported_Aggregates!K4 -> 24 | F16: =Calculated_Summary!K4 -> 24 | G16: =Calculated_Summary!L4 -> 1.5
A17: Smart Factory | B17: Sensor Data | C17: Delay (ms) | D17: =Reported_Aggregates!B5 -> Sensor Data | E17: =Reported_Aggregates!C5 -> 38.9 | F17: =Calculated_Summary!C5 -> 38.9 | G17: =Calculated_Summary!D5 -> 2.1
A18: Smart Factory | B18: Sensor Data | C18: Jitter (ms) | D18: =Reported_Aggregates!D5 -> 2.1 | E18: =Reported_Aggregates!E5 -> 6.3 | F18: =Calculated_Summary!E5 -> 6.3 | G18: =Calculated_Summary!F5 -> 0.8
A19: Smart Factory | B19: Sensor Data | C19: PDR (%) | D19: =Reported_Aggregates!F5 -> 0.8 | E19: =Reported_Aggregates!G5 -> 99.1 | F19: =Calculated_Summary!G5 -> 99.1 | G19: =Calculated_Summary!H5 -> 0.4
A20: Smart Factory | B20: Sensor Data | C20: Throughput (kbps) | D20: =Reported_Aggregates!H5 -> 0.4 | E20: =Reported_Aggregates!I5 -> 420 | F20: =Calculated_Summary!I5 -> 420 | G20: =Calculated_Summary!J5 -> 15
A21: Smart Factory | B21: Sensor Data | C21: CPU Load (%) | D21: =Reported_Aggregates!J5 -> 15 | E21: =Reported_Aggregates!K5 -> 23 | F21: =Calculated_Summary!K5 -> 23 | G21: =Calculated_Summary!L5 -> 1.2
A22: Smart Factory | B22: Maintenance Upload | C22: Delay (ms) | D22: =Reported_Aggregates!B6 -> Maintenance Upload | E22: =Reported_Aggregates!C6 -> 76.2 | F22: =Calculated_Summary!C6 -> 76.2 | G22: =Calculated_Summary!D6 -> 4.8
A23: Smart Factory | B23: Maintenance Upload | C23: Jitter (ms) | D23: =Reported_Aggregates!D6 -> 4.8 | E23: =Reported_Aggregates!E6 -> 12.1 | F23: =Calculated_Summary!E6 -> 12.1 | G23: =Calculated_Summary!F6 -> 1
A24: Smart Factory | B24: Maintenance Upload | C24: PDR (%) | D24: =Reported_Aggregates!F6 -> 1 | E24: =Reported_Aggregates!G6 -> 99.5 | F24: =Calculated_Summary!G6 -> 99.5 | G24: =Calculated_Summary!H6 -> 0.2
A25: Smart Factory | B25: Maintenance Upload | C25: Throughput (kbps) | D25: =Reported_Aggregates!H6 -> 0.2 | E25: =Reported_Aggregates!I6 -> 800 | F25: =Calculated_Summary!I6 -> 800 | G25: =Calculated_Summary!J6 -> 18
A26: Smart Factory | B26: Maintenance Upload | C26: CPU Load (%) | D26: =Reported_Aggregates!J6 -> 18 | E26: =Reported_Aggregates!K6 -> 25 | F26: =Calculated_Summary!K6 -> 25 | G26: =Calculated_Summary!L6 -> 1.4
A27: Medical IoT | B27: ECG Stream | C27: Delay (ms) | D27: =Reported_Aggregates!B7 -> ECG Stream | E27: =Reported_Aggregates!C7 -> 19.7 | F27: =Calculated_Summary!C7 -> 19.7 | G27: =Calculated_Summary!D7 -> 1.2
A28: Medical IoT | B28: ECG Stream | C28: Jitter (ms) | D28: =Reported_Aggregates!D7 -> 1.2 | E28: =Reported_Aggregates!E7 -> 3.2 | F28: =Calculated_Summary!E7 -> 3.2 | G28: =Calculated_Summary!F7 -> 0.3
A29: Medical IoT | B29: ECG Stream | C29: PDR (%) | D29: =Reported_Aggregates!F7 -> 0.3 | E29: =Reported_Aggregates!G7 -> 97.8 | F29: =Calculated_Summary!G7 -> 97.8 | G29: =Calculated_Summary!H7 -> 0.8
A30: Medical IoT | B30: ECG Stream | C30: Throughput (kbps) | D30: =Reported_Aggregates!H7 -> 0.8 | E30: =Reported_Aggregates!I7 -> 260 | F30: =Calculated_Summary!I7 -> 260 | G30: =Calculated_Summary!J7 -> 10
A31: Medical IoT | B31: ECG Stream | C31: CPU Load (%) | D31: =Reported_Aggregates!J7 -> 10 | E31: =Reported_Aggregates!K7 -> 28 | F31: =Calculated_Summary!K7 -> 28 | G31: =Calculated_Summary!L7 -> 1.6
A32: Medical IoT | B32: Vital Signs | C32: Delay (ms) | D32: =Reported_Aggregates!B8 -> Vital Signs | E32: =Reported_Aggregates!C8 -> 33.2 | F32: =Calculated_Summary!C8 -> 33.2 | G32: =Calculated_Summary!D8 -> 1.9
A33: Medical IoT | B33: Vital Signs | C33: Jitter (ms) | D33: =Reported_Aggregates!D8 -> 1.9 | E33: =Reported_Aggregates!E8 -> 5.5 | F33: =Calculated_Summary!E8 -> 5.5 | G33: =Calculated_Summary!F8 -> 0.7
A34: Medical IoT | B34: Vital Signs | C34: PDR (%) | D34: =Reported_Aggregates!F8 -> 0.7 | E34: =Reported_Aggregates!G8 -> 99 | F34: =Calculated_Summary!G8 -> 99 | G34: =Calculated_Summary!H8 -> 0.4
A35: Medical IoT | B35: Vital Signs | C35: Throughput (kbps) | D35: =Reported_Aggregates!H8 -> 0.4 | E35: =Reported_Aggregates!I8 -> 330 | F35: =Calculated_Summary!I8 -> 330 | G35: =Calculated_Summary!J8 -> 11
A36: Medical IoT | B36: Vital Signs | C36: CPU Load (%) | D36: =Reported_Aggregates!J8 -> 11 | E36: =Reported_Aggregates!K8 -> 19.4 | F36: =Calculated_Summary!K8 -> 19.4 | G36: =Calculated_Summary!L8 -> 1.1
A37: Medical IoT | B37: Link Disruption | C37: Delay (ms) | D37: =Reported_Aggregates!B9 -> Link Disruption | E37: =Reported_Aggregates!C9 -> 41.5 | F37: =Calculated_Summary!C9 -> 41.5 | G37: =Calculated_Summary!D9 -> 2.8
A38: Medical IoT | B38: Link Disruption | C38: Jitter (ms) | D38: =Reported_Aggregates!D9 -> 2.8 | E38: =Reported_Aggregates!E9 -> 6.1 | F38: =Calculated_Summary!E9 -> 6.1 | G38: =Calculated_Summary!F9 -> 0.9
A39: Medical IoT | B39: Link Disruption | C39: PDR (%) | D39: =Reported_Aggregates!F9 -> 0.9 | E39: =Reported_Aggregates!G9 -> 95.4 | F39: =Calculated_Summary!G9 -> 95.4 | G39: =Calculated_Summary!H9 -> 1.2
A40: Medical IoT | B40: Link Disruption | C40: Throughput (kbps) | D40: =Reported_Aggregates!H9 -> 1.2 | E40: =Reported_Aggregates!I9 -> 310 | F40: =Calculated_Summary!I9 -> 310 | G40: =Calculated_Summary!J9 -> 13
...

Sheet Charts
A1: Reported Mean Delay by Traffic Condition
